Workbook
Name DepartmentList: 'DEPARTMENT REFLECTION'!$A$2:$A$14

Sheet SEARCH
A1: LFL 2026 — Personal Session Finder
A2: Type a full or partial name in B4. The first matching participant will appear below.
A4: Search name
A5: Select department
A6: Participant | B6: =IF($B$4="","",IFERROR(XLOOKUP("*"&$B$4&"*",'PARTICIPANT DIRECTORY'!$A$2:$A$200,'PARTICIPANT DIRECTORY'!$A$2:$A$200,"No matching name",2),"No matching name"))
A8: Session | B8: Time | C8: Session title | D8: Presenter(s) | E8: Venue | F8: Department / Notes
A9: Breakout 1 | B9: 10:00–10:45 | C9: =IFERROR(XLOOKUP($B$6,'PARTICIPANT DIRECTORY'!$A$2:$A$200,'PARTICIPANT DIRECTORY'!$D$2:$D$200,""),"") | D9: =IFERROR(XLOOKUP($B$6,'PARTICIPANT DIRECTORY'!$A$2:$A$200,'PARTICIPANT DIRECTORY'!$E$2:$E$200,""),"") | E9: =IFERROR(XLOOKUP($B$6,'PARTICIPANT DIRECTORY'!$A$2:$A$200,'PARTICIPANT DIRECTORY'!$F$2:$F$200,""),"")
A10: Breakout 2 | B10: 11:00–11:45 | C10: =IFERROR(XLOOKUP($B$6,'PARTICIPANT DIRECTORY'!$A$2:$A$200,'PARTICIPANT DIRECTORY'!$I$2:$I$200,""),"") | D10: =IFERROR(XLOOKUP($B$6,'PARTICIPANT DIRECTORY'!$A$2:$A$200,'PARTICIPANT DIRECTORY'!$J$2:$J$200,""),"") | E10: =IFERROR(XLOOKUP($B$6,'PARTICIPANT DIRECTORY'!$A$2:$A$200,'PARTICIPANT DIRECTORY'!$K$2:$K$200,""),"")
A11: Department Reflection | B11: 11:50–12:30 | C11: Department Reflection & Consolidation | D11: =IFERROR(XLOOKUP($B$5,'DEPARTMENT REFLECTION'!$A$2:$A$20,'DEPARTMENT REFLECTION'!$C$2:$C$20,""),"") | E11: =IFERROR(XLOOKUP($B$5,'DEPARTMENT REFLECTION'!$A$2:$A$20,'DEPARTMENT REFLECTION'!$B$2:$B$20,""),"") | F11: =$B$5
A13: Choose your department from the green dropdown above to display the correct Department Reflection venue and facilitator.

Sheet PARTICIPANT DIRECTORY
A1: Name | B1: Breakout 1 Time | C1: Breakout 1 Session | D1: Breakout 1 Title | E1: Breakout 1 Presenter(s) | F1: Breakout 1 Venue | G1: Breakout 2 Time | H1: Breakout 2 Session | I1: Breakout 2 Title | J1: Breakout 2 Presenter(s) | K1: Breakout 2 Venue | L1: Department | M1: Department Reflection Venue | N1: Department Reflection Facilitator
A2: Abel Ang En Pei | B2: 10:00–10:45 | C2: Breakout 1 | D2: Dialogic Talk for Thoughtful Thinkers | E2: Sasha Kaur dhillon | F2: G301 | G2: 11:00–11:45 | H2: Breakout 2 | I2: AI as Feedback, Not Fallback: Developing Critical Thinking Using AI | J2: Chen Ying & Brendon Chee | K2: B105 | M2: =IFERROR(XLOOKUP(L2,'DEPARTMENT REFLECTION'!$A$2:$A$20,'DEPARTMENT REFLECTION'!$B$2:$B$20,""),"") | N2: =IFERROR(XLOOKUP(L2,'DEPARTMENT REFLECTION'!$A$2:$A$20,'DEPARTMENT REFLECTION'!$C$2:$C$20,""),"")
A3: Adriel Thin Jie Hao | B3: 10:00–10:45 | C3: Breakout 1 | D3: Exploring the Use of Non-Linear Pedagogy Principles to Deepen Student Learning in Physical Education | E3: Francis Lee | F3: E103 | G3: 11:00–11:45 | H3: Breakout 2 | I3: Cultivating Self-Directedness, Co-Constructing Success | J3: Anuthama & Esther Wang | K3: E101 | M3: =IFERROR(XLOOKUP(L3,'DEPARTMENT REFLECTION'!$A$2:$A$20,'DEPARTMENT REFLECTION'!$B$2:$B$20,""),"") | N3: =IFERROR(XLOOKUP(L3,'DEPARTMENT REFLECTION'!$A$2:$A$20,'DEPARTMENT REFLECTION'!$C$2:$C$20,""),"")
A4: Aliya Yusaf Ansari | B4: 10:00–10:45 | C4: Breakout 1 | D4: Dialogic Talk for Thoughtful Thinkers | E4: Sasha Kaur dhillon | F4: G301 | G4: 11:00–11:45 | H4: Breakout 2 | I4: Experimenting with a Pedagogy of Discomfort in the GP Classroom | J4: Maryam Mohamed Mokhtar | K4: B109 | M4: =IFERROR(XLOOKUP(L4,'DEPARTMENT REFLECTION'!$A$2:$A$20,'DEPARTMENT REFLECTION'!$B$2:$B$20,""),"") | N4: =IFERROR(XLOOKUP(L4,'DEPARTMENT REFLECTION'!$A$2:$A$20,'DEPARTMENT REFLECTION'!$C$2:$C$20,""),"")
A5: Ang Eng Oon Aaron | B5: 10:00–10:45 | C5: Breakout 1 | D5: Dialogic Talk for Thoughtful Thinkers | E5: Sasha Kaur dhillon | F5: G301 | G5: 11:00–11:45 | H5: Breakout 2 | I5: AI as Feedback, Not Fallback: Developing Critical Thinking Using AI | J5: Chen Ying & Brendon Chee | K5: B105 | M5: =IFERROR(XLOOKUP(L5,'DEPARTMENT REFLECTION'!$A$2:$A$20,'DEPARTMENT REFLECTION'!$B$2:$B$20,""),"") | N5: =IFERROR(XLOOKUP(L5,'DEPARTMENT REFLECTION'!$A$2:$A$20,'DEPARTMENT REFLECTION'!$C$2:$C$20,""),"")
A6: Ang Mei Ling | B6: 10:00–10:45 | C6: Breakout 1 | D6: AI in Mathematics: See the Thinking, Shape the Learning, Spark Joy | E6: Ng Lay Ling | F6: B109 | G6: 11:00–11:45 | H6: Breakout 2 | I6: Use of Brisk Teaching: Practical Strategies to Develop Metacognition and Adaptive Thinking through Form | J6: Alan Varella & Cyrene Tan | K6: E104 | M6: =IFERROR(XLOOKUP(L6,'DEPARTMENT REFLECTION'!$A$2:$A$20,'DEPARTMENT REFLECTION'!$B$2:$B$20,""),"") | N6: =IFERROR(XLOOKUP(L6,'DEPARTMENT REFLECTION'!$A$2:$A$20,'DEPARTMENT REFLECTION'!$C$2:$C$20,""),"")
A7: Ang Wan Yu, Florence | B7: 10:00–10:45 | C7: Breakout 1 | D7: Multimodal Learning for Multi-Faceted Development of e21CC Skills | E7: Florence Ang & Caroline Sng | F7: B106 | G7: 11:00–11:45 | H7: Breakout 2 | I7: Experimenting with a Pedagogy of Discomfort in the GP Classroom | J7: Maryam Mohamed Mokhtar | K7: B109 | M7: =IFERROR(XLOOKUP(L7,'DEPARTMENT REFLECTION'!$A$2:$A$20,'DEPARTMENT REFLECTION'!$B$2:$B$20,""),"") | N7: =IFERROR(XLOOKUP(L7,'DEPARTMENT REFLECTION'!$A$2:$A$20,'DEPARTMENT REFLECTION'!$C$2:$C$20,""),"")
A8: Ang Yam Hui | B8: 10:00–10:45 | C8: Breakout 1 | D8: AI in Mathematics: See the Thinking, Shape the Learning, Spark Joy | E8: Ng Lay Ling | F8: B109 | G8: 11:00–11:45 | H8: Breakout 2 | I8: AIMS vs Gemini: What AI Feedback Reveals About Student Writing (And What It Might Not) | J8: Irene Kuek & Lin Pei-Chen | K8: E103 | M8: =IFERROR(XLOOKUP(L8,'DEPARTMENT REFLECTION'!$A$2:$A$20,'DEPARTMENT REFLECTION'!$B$2:$B$20,""),"") | N8: =IFERROR(XLOOKUP(L8,'DEPARTMENT REFLECTION'!$A$2:$A$20,'DEPARTMENT REFLECTION'!$C$2:$C$20,""),"")
A9: Anuthama | B9: 10:00–10:45 | C9: Breakout 1 | D9: Dialogic Talk for Thoughtful Thinkers | E9: Sasha Kaur dhillon | F9: G301 | G9: 11:00–11:45 | H9: Breakout 2 | I9: Cultivating Self-Directedness, Co-Constructing Success | J9: Anuthama & Esther Wang | K9: E101 | M9: =IFERROR(XLOOKUP(L9,'DEPARTMENT REFLECTION'!$A$2:$A$20,'DEPARTMENT REFLECTION'!$B$2:$B$20,""),"") | N9: =IFERROR(XLOOKUP(L9,'DEPARTMENT REFLECTION'!$A$2:$A$20,'DEPARTMENT REFLECTION'!$C$2:$C$20,""),"")
A10: Azahar B Dahlan | B10: 10:00–10:45 | C10: Breakout 1 | D10: Multimodal Learning for Multi-Faceted Development of e21CC Skills | E10: Florence Ang & Caroline Sng | F10: B106 | G10: 11:00–11:45 | H10: Breakout 2 | I10: Empowering Students to Understand Concepts, Not Just Content | J10: Trevor Tay & Nuryani Suneh | K10: B110 | M10: =IFERROR(XLOOKUP(L10,'DEPARTMENT REFLECTION'!$A$2:$A$20,'DEPARTMENT REFLECTION'!$B$2:$B$20,""),"") | N10: =IFERROR(XLOOKUP(L10,'DEPARTMENT REFLECTION'!$A$2:$A$20,'DEPARTMENT REFLECTION'!$C$2:$C$20,""),"")
A11: Chan Hui Lin | B11: 10:00–10:45 | C11: Breakout 1 | D11: Dialogic Talk for Thoughtful Thinkers | E11: Sasha Kaur dhillon | F11: G301 | G11: 11:00–11:45 | H11: Breakout 2 | I11: AI as Feedback, Not Fallback: Developing Critical Thinking Using AI | J11: Chen Ying & Brendon Chee | K11: B105 | M11: =IFERROR(XLOOKUP(L11,'DEPARTMENT REFLECTION'!$A$2:$A$20,'DEPARTMENT REFLECTION'!$B$2:$B$20,""),"") | N11: =IFERROR(XLOOKUP(L11,'DEPARTMENT REFLECTION'!$A$2:$A$20,'DEPARTMENT REFLECTION'!$C$2:$C$20,""),"")
A12: CHANG XIAO PING, JULIAN | B12: 10:00–10:45 | C12: Breakout 1 | D12: Multimodal Learning for Multi-Faceted Development of e21CC Skills | E12: Florence Ang & Caroline Sng | F12: B106 | G12: 11:00–11:45 | H12: Breakout 2 | I12: Cultivating Self-Directedness, Co-Constructing Success | J12: Anuthama & Esther Wang | K12: E101 | M12: =IFERROR(XLOOKUP(L12,'DEPARTMENT REFLECTION'!$A$2:$A$20,'DEPARTMENT REFLECTION'!$B$2:$B$20,""),"") | N12: =IFERROR(XLOOKUP(L12,'DEPARTMENT REFLECTION'!$A$2:$A$20,'DEPARTMENT REFLECTION'!$C$2:$C$20,""),"")
A13: Chee Yao Rong Brendon | B13: 10:00–10:45 | C13: Breakout 1 | D13: Fostering Student Passion in Project Work Using the From Near to Far Framework | E13: Mariya Ahmad | F13: E104 | G13: 11:00–11:45 | H13: Breakout 2 | I13: AI as Feedback, Not Fallback: Developing Critical Thinking Using AI | J13: Chen Ying & Brendon Chee | K13: B105 | M13: =IFERROR(XLOOKUP(L13,'DEPARTMENT REFLECTION'!$A$2:$A$20,'DEPARTMENT REFLECTION'!$B$2:$B$20,""),"") | N13: =IFERROR(XLOOKUP(L13,'DEPARTMENT REFLECTION'!$A$2:$A$20,'DEPARTMENT REFLECTION'!$C$2:$C$20,""),"")
... A32: Ivy Liew Wei Xin | B32: 10:00–10:45 | C32: Breakout 1 | D32: Fostering Student Passion in Project Work Using the From Near to Far Framework | E32: Mariya Ahmad | F32: E104 | G32: 11:00–11:45 | H32: Breakout 2 | I32: Cultivating Self-Directedness, Co-Constructing Success | J32: Anuthama & Esther Wang | K32: E101 | M32: =IFERROR(XLOOKUP(L32,'DEPARTMENT REFLECTION'!$A$2:$A$20,'DEPARTMENT REFLECTION'!$B$2:$B$20,""),"") | N32: =IFERROR(XLOOKUP(L32,'DEPARTMENT REFLECTION'!$A$2:$A$20,'DEPARTMENT REFLECTION'!$C$2:$C$20,""),"")
A33: Jismyl Lam | B33: 10:00–10:45 | C33: Breakout 1 | G33: 11:00–11:45 | H33: Breakout 2 | I33: Empowering Students to Understand Concepts, Not Just Content | J33: Trevor Tay & Nuryani Suneh | K33: B110 | M33: =IFERROR(XLOOKUP(L33,'DEPARTMENT REFLECTION'!$A$2:$A$20,'DEPARTMENT REFLECTION'!$B$2:$B$20,""),"") | N33: =IFERROR(XLOOKUP(L33,'DEPARTMENT REFLECTION'!$A$2:$A$20,'DEPARTMENT REFLECTION'!$C$2:$C$20,""),"")
A34: Joash Lee Kah Fai | B34: 10:00–10:45 | C34: Breakout 1 | D34: Dialogic Talk for Thoughtful Thinkers | E34: Sasha Kaur dhillon | F34: G301 | G34: 11:00–11:45 | H34: Breakout 2 | I34: Experimenting with a Pedagogy of Discomfort in the GP Classroom | J34: Maryam Mohamed Mokhtar | K34: B109 | M34: =IFERROR(XLOOKUP(L34,'DEPARTMENT REFLECTION'!$A$2:$A$20,'DEPARTMENT REFLECTION'!$B$2:$B$20,""),"") | N34: =IFERROR(XLOOKUP(L34,'DEPARTMENT REFLECTION'!$A$2:$A$20,'DEPARTMENT REFLECTION'!$C$2:$C$20,""),"")
A35: K. Veerapandiyan | B35: 10:00–10:45 | C35: Breakout 1 | D35: Fostering Student Passion in Project Work Using the From Near to Far Framework | E35: Mariya Ahmad | F35: E104 | G35: 11:00–11:45 | H35: Breakout 2 | I35: Empowering Students to Understand Concepts, Not Just Content | J35: Trevor Tay & Nuryani Suneh | K35: B110 | M35: =IFERROR(XLOOKUP(L35,'DEPARTMENT REFLECTION'!$A$2:$A$20,'DEPARTMENT REFLECTION'!$B$2:$B$20,""),"") | N35: =IFERROR(XLOOKUP(L35,'DEPARTMENT REFLECTION'!$A$2:$A$20,'DEPARTMENT REFLECTION'!$C$2:$C$20,""),"")
A36: Kat Kar Hwee | B36: 10:00–10:45 | C36: Breakout 1 | D36: Multimodal Learning for Multi-Faceted Development of e21CC Skills | E36: Florence Ang & Caroline Sng | F36: B106 | G36: 11:00–11:45 | H36: Breakout 2 | I36: Evidence-Driven Decision-Making: Using Student Data to Complement Teacher Observations | J36: Christabelle Soh | K36: B106 | M36: =IFERROR(XLOOKUP(L36,'DEPARTMENT REFLECTION'!$A$2:$A$20,'DEPARTMENT REFLECTION'!$B$2:$B$20,""),"") | N36: =IFERROR(XLOOKUP(L36,'DEPARTMENT REFLECTION'!$A$2:$A$20,'DEPARTMENT REFLECTION'!$C$2:$C$20,""),"")
A37: Khairul Anwar Bin Ali | B37: 10:00–10:45 | C37: Breakout 1 | D37: Multimodal Learning for Multi-Faceted Development of e21CC Skills | E37: Florence Ang & Caroline Sng | F37: B106 | G37: 11:00–11:45 | H37: Breakout 2 | I37: Use of Brisk Teaching: Practical Strategies to Develop Metacognition and Adaptive Thinking through Form | J37: Alan Varella & Cyrene Tan | K37: E104 | M37: =IFERROR(XLOOKUP(L37,'DEPARTMENT REFLECTION'!$A$2:$A$20,'DEPARTMENT REFLECTION'!$B$2:$B$20,""),"") | N37: =IFERROR(XLOOKUP(L37,'DEPARTMENT REFLECTION'!$A$2:$A$20,'DEPARTMENT REFLECTION'!$C$2:$C$20,""),"")
A38: Koh Rui Yang (Xu Ruiyang) | B38: 10:00–10:45 | C38: Breakout 1 | D38: Dialogic Talk for Thoughtful Thinkers | E38: Sasha Kaur dhillon | F38: G301 | G38: 11:00–11:45 | H38: Breakout 2 | I38: Experimenting with a Pedagogy of Discomfort in the GP Classroom | J38: Maryam Mohamed Mokhtar | K38: B109 | M38: =IFERROR(XLOOKUP(L38,'DEPARTMENT REFLECTION'!$A$2:$A$20,'DEPARTMENT REFLECTION'!$B$2:$B$20,""),"") | N38: =IFERROR(XLOOKUP(L38,'DEPARTMENT REFLECTION'!$A$2:$A$20,'DEPARTMENT REFLECTION'!$C$2:$C$20,""),"")
A39: Kok Hui Ching | B39: 10:00–10:45 | C39: Breakout 1 | D39: Multimodal Learning for Multi-Faceted Development of e21CC Skills | E39: Florence Ang & Caroline Sng | F39: B106 | G39: 11:00–11:45 | H39: Breakout 2 | I39: Cultivating Self-Directedness, Co-Constructing Success | J39: Anuthama & Esther Wang | K39: E101 | M39: =IFERROR(XLOOKUP(L39,'DEPARTMENT REFLECTION'!$A$2:$A$20,'DEPARTMENT REFLECTION'!$B$2:$B$20,""),"") | N39: =IFERROR(XLOOKUP(L39,'DEPARTMENT REFLECTION'!$A$2:$A$20,'DEPARTMENT REFLECTION'!$C$2:$C$20,""),"")
A40: Kua Jing Han | B40: 10:00–10:45 | C40: Breakout 1 | D40: AI in Mathematics: See the Thinking, Shape the Learning, Spark Joy | E40: Ng Lay Ling | F40: B109 | G40: 11:00–11:45 | H40: Breakout 2 | I40: AI as Feedback, Not Fallback: Developing Critical Thinking Using AI | J40: Chen Ying & Brendon Chee | K40: B105 | M40: =IFERROR(XLOOKUP(L40,'DEPARTMENT REFLECTION'!$A$2:$A$20,'DEPARTMENT REFLECTION'!$B$2:$B$20,""),"") | N40: =IFERROR(XLOOKUP(L40,'DEPARTMENT REFLECTION'!$A$2:$A$20,'DEPARTMENT REFLECTION'!$C$2:$C$20,""),"")
A41: Kwek Ee Hui, Irene | B41: 10:00–10:45 | C41: Breakout 1 | D41: AI-ding Students' Preparation for Oral Examinations: 6. Using Technology for Real-World Skills | E41: Ho Jia Xuan Jane | F41: E101 | G41: 11:00–11:45 | H41: Breakout 2 | I41: AIMS vs Gemini: What AI Feedback Reveals About Student Writing (And What It Might Not) | J41: Irene Kuek & Lin Pei-Chen | K41: E103 | M41: =IFERROR(XLOOKUP(L41,'DEPARTMENT REFLECTION'!$A$2:$A$20,'DEPARTMENT REFLECTION'!$B$2:$B$20,""),"") | N41: =IFERROR(XLOOKUP(L41,'DEPARTMENT REFLECTION'!$A$2:$A$20,'DEPARTMENT REFLECTION'!$C$2:$C$20,""),"")
A42: Lam Cherng Yang | B42: 10:00–10:45 | C42: Breakout 1 | D42: Multimodal Learning for Multi-Faceted Development of e21CC Skills | E42: Florence Ang & Caroline Sng | F42: B106 | G42: 11:00–11:45 | H42: Breakout 2 | I42: Experimenting with a Pedagogy of Discomfort in the GP Classroom | J42: Maryam Mohamed Mokhtar | K42: B109 | M42: =IFERROR(XLOOKUP(L42,'DEPARTMENT REFLECTION'!$A$2:$A$20,'DEPARTMENT REFLECTION'!$B$2:$B$20,""),"") | N42: =IFERROR(XLOOKUP(L42,'DEPARTMENT REFLECTION'!$A$2:$A$20,'DEPARTMENT REFLECTION'!$C$2:$C$20,""),"")
A43: Lau Fook Choy | B43: 10:00–10:45 | C43: Breakout 1 | D43: AI in Mathematics: See the Thinking, Shape the Learning, Spark Joy | E43: Ng Lay Ling | F43: B109 | G43: 11:00–11:45 | H43: Breakout 2 | I43: Redesigning Mathematics Learning: Our ILP Journey and Pedagogical Shifts | J43: Kelvin Ng & Leonard Lau | K43: E102 | M43: =IFERROR(XLOOKUP(L43,'DEPARTMENT REFLECTION'!$A$2:$A$20,'DEPARTMENT REFLECTION'!$B$2:$B$20,""),"") | N43: =IFERROR(XLOOKUP(L43,'DEPARTMENT REFLECTION'!$A$2:$A$20,'DEPARTMENT REFLECTION'!$C$2:$C$20,""),"")
A44: Lau Wee Lip Jonathan | B44: 10:00–10:45 | C44: Breakout 1 | D44: AI in Mathematics: See the Thinking, Shape the Learning, Spark Joy | E44: Ng Lay Ling | F44: B109 | G44: 11:00–11:45 | H44: Breakout 2 | I44: AI as Feedback, Not Fallback: Developing Critical Thinking Using AI | J44: Chen Ying & Brendon Chee | K44: B105 | M44: =IFERROR(XLOOKUP(L44,'DEPARTMENT REFLECTION'!$A$2:$A$20,'DEPARTMENT REFLECTION'!$B$2:$B$20,""),"") | N44: =IFERROR(XLOOKUP(L44,'DEPARTMENT REFLECTION'!$A$2:$A$20,'DEPARTMENT REFLECTION'!$C$2:$C$20,""),"")
A45: Laycock Eng Yeow Gary | B45: 10:00–10:45 | C45: Breakout 1 | D45: Dialogic Talk for Thoughtful Thinkers | E45: Sasha Kaur dhillon | F45: G301 | G45: 11:00–11:45 | H45: Breakout 2 | I45: AI as Feedback, Not Fallback: Developing Critical Thinking Using AI | J45: Chen Ying & Brendon Chee | K45: B105 | M45: =IFERROR(XLOOKUP(L45,'DEPARTMENT REFLECTION'!$A$2:$A$20,'DEPARTMENT REFLECTION'!$B$2:$B$20,""),"") | N45: =IFERROR(XLOOKUP(L45,'DEPARTMENT REFLECTION'!$A$2:$A$20,'DEPARTMENT REFLECTION'!$C$2:$C$20,""),"")
... A64: Mariya Binte Ahmad | B64: 10:00–10:45 | C64: Breakout 1 | D64: Fostering Student Passion in Project Work Using the From Near to Far Framework | E64: Mariya Ahmad | F64: E104 | G64: 11:00–11:45 | H64: Breakout 2 | I64: Experimenting with a Pedagogy of Discomfort in the GP Classroom | J64: Maryam Mohamed Mokhtar | K64: B109 | M64: =IFERROR(XLOOKUP(L64,'DEPARTMENT REFLECTION'!$A$2:$A$20,'DEPARTMENT REFLECTION'!$B$2:$B$20,""),"") | N64: =IFERROR(XLOOKUP(L64,'DEPARTMENT REFLECTION'!$A$2:$A$20,'DEPARTMENT REFLECTION'!$C$2:$C$20,""),"")
A65: Mark Chan | B65: 10:00–10:45 | C65: Breakout 1 | D65: Dialogic Talk for Thoughtful Thinkers | E65: Sasha Kaur dhillon | F65: G301 | G65: 11:00–11:45 | H65: Breakout 2 | M65: =IFERROR(XLOOKUP(L65,'DEPARTMENT REFLECTION'!$A$2:$A$20,'DEPARTMENT REFLECTION'!$B$2:$B$20,""),"") | N65: =IFERROR(XLOOKUP(L65,'DEPARTMENT REFLECTION'!$A$2:$A$20,'DEPARTMENT REFLECTION'!$C$2:$C$20,""),"")
A66: Maryam Binte Mohamed Mokhtar | B66: 10:00–10:45 | C66: Breakout 1 | D66: Dialogic Talk for Thoughtful Thinkers | E66: Sasha Kaur dhillon | F66: G301 | G66: 11:00–11:45 | H66: Breakout 2 | I66: Experimenting with a Pedagogy of Discomfort in the GP Classroom | J66: Maryam Mohamed Mokhtar | K66: B109 | M66: =IFERROR(XLOOKUP(L66,'DEPARTMENT REFLECTION'!$A$2:$A$20,'DEPARTMENT REFLECTION'!$B$2:$B$20,""),"") | N66: =IFERROR(XLOOKUP(L66,'DEPARTMENT REFLECTION'!$A$2:$A$20,'DEPARTMENT REFLECTION'!$C$2:$C$20,""),"")
A67: Mok Yuerong Esther | B67: 10:00–10:45 | C67: Breakout 1 | D67: Dialogic Talk for Thoughtful Thinkers | E67: Sasha Kaur dhillon | F67: G301 | G67: 11:00–11:45 | H67: Breakout 2 | I67: Evidence-Driven Decision-Making: Using Student Data to Complement Teacher Observations | J67: Christabelle Soh | K67: B106 | M67: =IFERROR(XLOOKUP(L67,'DEPARTMENT REFLECTION'!$A$2:$A$20,'DEPARTMENT REFLECTION'!$B$2:$B$20,""),"") | N67: =IFERROR(XLOOKUP(L67,'DEPARTMENT REFLECTION'!$A$2:$A$20,'DEPARTMENT REFLECTION'!$C$2:$C$20,""),"")
A68: Nam Aileen Mrs.Lim Kai Chuan Aileen | B68: 10:00–10:45 | C68: Breakout 1 | D68: AI and AA: An Attempt at Amalgamation | E68: Low Kian Seh | F68: E102 | G68: 11:00–11:45 | H68: Breakout 2 | I68: Evidence-Driven Decision-Making: Using Student Data to Complement Teacher Observations | J68: Christabelle Soh | K68: B106 | M68: =IFERROR(XLOOKUP(L68,'DEPARTMENT REFLECTION'!$A$2:$A$20,'DEPARTMENT REFLECTION'!$B$2:$B$20,""),"") | N68: =IFERROR(XLOOKUP(L68,'DEPARTMENT REFLECTION'!$A$2:$A$20,'DEPARTMENT REFLECTION'!$C$2:$C$20,""),"")
A69: Neo Kian Siah | B69: 10:00–10:45 | C69: Breakout 1 | D69: AI in Mathematics: See the Thinking, Shape the Learning, Spark Joy | E69: Ng Lay Ling | F69: B109 | G69: 11:00–11:45 | H69: Breakout 2 | I69: Use of Brisk Teaching: Practical Strategies to Develop Metacognition and Adaptive Thinking through Form | J69: Alan Varella & Cyrene Tan | K69: E104 | M69: =IFERROR(XLOOKUP(L69,'DEPARTMENT REFLECTION'!$A$2:$A$20,'DEPARTMENT REFLECTION'!$B$2:$B$20,""),"") | N69: =IFERROR(XLOOKUP(L69,'DEPARTMENT REFLECTION'!$A$2:$A$20,'DEPARTMENT REFLECTION'!$C$2:$C$20,""),"")
A70: Ng Ee Lin Evelyn | B70: 10:00–10:45 | C70: Breakout 1 | D70: Leveraging on the Student Learning Space (SLS) to Enhance Global Literacy | E70: Niki Lee | F70: B105 | G70: 11:00–11:45 | H70: Breakout 2 | I70: AIMS vs Gemini: What AI Feedback Reveals About Student Writing (And What It Might Not) | J70: Irene Kuek & Lin Pei-Chen | K70: E103 | M70: =IFERROR(XLOOKUP(L70,'DEPARTMENT REFLECTION'!$A$2:$A$20,'DEPARTMENT REFLECTION'!$B$2:$B$20,""),"") | N70: =IFERROR(XLOOKUP(L70,'DEPARTMENT REFLECTION'!$A$2:$A$20,'DEPARTMENT REFLECTION'!$C$2:$C$20,""),"")
A71: Ng Lay Ling | B71: 10:00–10:45 | C71: Breakout 1 | D71: AI in Mathematics: See the Thinking, Shape the Learning, Spark Joy | E71: Ng Lay Ling | F71: B109 | G71: 11:00–11:45 | H71: Breakout 2 | I71: Redesigning Mathematics Learning: Our ILP Journey and Pedagogical Shifts | J71: Kelvin Ng & Leonard Lau | K71: E102 | M71: =IFERROR(XLOOKUP(L71,'DEPARTMENT REFLECTION'!$A$2:$A$20,'DEPARTMENT REFLECTION'!$B$2:$B$20,""),"") | N71: =IFERROR(XLOOKUP(L71,'DEPARTMENT REFLECTION'!$A$2:$A$20,'DEPARTMENT REFLECTION'!$C$2:$C$20,""),"")
A72: Ng Seng Chang | B72: 10:00–10:45 | C72: Breakout 1 | D72: AI and AA: An Attempt at Amalgamation | E72: Low Kian Seh | F72: E102 | G72: 11:00–11:45 | H72: Breakout 2 | I72: Redesigning Mathematics Learning: Our ILP Journey and Pedagogical Shifts | J72: Kelvin Ng & Leonard Lau | K72: E102 | M72: =IFERROR(XLOOKUP(L72,'DEPARTMENT REFLECTION'!$A$2:$A$20,'DEPARTMENT REFLECTION'!$B$2:$B$20,""),"") | N72: =IFERROR(XLOOKUP(L72,'DEPARTMENT REFLECTION'!$A$2:$A$20,'DEPARTMENT REFLECTION'!$C$2:$C$20,""),"")
A73: Ng Wei Ling | B73: 10:00–10:45 | C73: Breakout 1 | D73: AI in Mathematics: See the Thinking, Shape the Learning, Spark Joy | E73: Ng Lay Ling | F73: B109 | G73: 11:00–11:45 | H73: Breakout 2 | I73: AIMS vs Gemini: What AI Feedback Reveals About Student Writing (And What It Might Not) | J73: Irene Kuek & Lin Pei-Chen | K73: E103 | M73: =IFERROR(XLOOKUP(L73,'DEPARTMENT REFLECTION'!$A$2:$A$20,'DEPARTMENT REFLECTION'!$B$2:$B$20,""),"") | N73: =IFERROR(XLOOKUP(L73,'DEPARTMENT REFLECTION'!$A$2:$A$20,'DEPARTMENT REFLECTION'!$C$2:$C$20,""),"")
A74: Ng Yon Tek, Kevin | B74: 10:00–10:45 | C74: Breakout 1 | D74: Dialogic Talk for Thoughtful Thinkers | E74: Sasha Kaur dhillon | F74: G301 | G74: 11:00–11:45 | H74: Breakout 2 | I74: Redesigning Mathematics Learning: Our ILP Journey and Pedagogical Shifts | J74: Kelvin Ng & Leonard Lau | K74: E102 | M74: =IFERROR(XLOOKUP(L74,'DEPARTMENT REFLECTION'!$A$2:$A$20,'DEPARTMENT REFLECTION'!$B$2:$B$20,""),"") | N74: =IFERROR(XLOOKUP(L74,'DEPARTMENT REFLECTION'!$A$2:$A$20,'DEPARTMENT REFLECTION'!$C$2:$C$20,""),"")
A75: Ngoh Kheng Kiat | B75: 10:00–10:45 | C75: Breakout 1 | D75: AI in Mathematics: See the Thinking, Shape the Learning, Spark Joy | E75: Ng Lay Ling | F75: B109 | G75: 11:00–11:45 | H75: Breakout 2 | I75: Redesigning Mathematics Learning: Our ILP Journey and Pedagogical Shifts | J75: Kelvin Ng & Leonard Lau | K75: E102 | M75: =IFERROR(XLOOKUP(L75,'DEPARTMENT REFLECTION'!$A$2:$A$20,'DEPARTMENT REFLECTION'!$B$2:$B$20,""),"") | N75: =IFERROR(XLOOKUP(L75,'DEPARTMENT REFLECTION'!$A$2:$A$20,'DEPARTMENT REFLECTION'!$C$2:$C$20,""),"")
A76: Noraziah Binte Abdul Aziz | B76: 10:00–10:45 | C76: Breakout 1 | D76: Dialogic Talk for Thoughtful Thinkers | E76: Sasha Kaur dhillon | F76: G301 | G76: 11:00–11:45 | H76: Breakout 2 | I76: Experimenting with a Pedagogy of Discomfort in the GP Classroom | J76: Maryam Mohamed Mokhtar | K76: B109 | M76: =IFERROR(XLOOKUP(L76,'DEPARTMENT REFLECTION'!$A$2:$A$20,'DEPARTMENT REFLECTION'!$B$2:$B$20,""),"") | N76: =IFERROR(XLOOKUP(L76,'DEPARTMENT REFLECTION'!$A$2:$A$20,'DEPARTMENT REFLECTION'!$C$2:$C$20,""),"")
...

Sheet DEPARTMENT REFLECTION
A1: Department | B1: Venue | C1: HOD / Facilitator
A2: Arts Department: Aesthetics (Art & Music) | B2: E109 | C2: Marcus Tay
A3: Arts Department: Humanities – JC(Economics, Geography & History) | B3: History Room | C3: Melissa
A4: Arts Department: Humanities – IP(Geography, History & Singapore Studies) | B4: Geography Room | C4: Brendon
A5: English Department – JC(General paper & Knowledge & Inquiry) | B5: B105 | C5: Faye
A6: English Department – IP(Language Arts & English Literature) | B6: B106 | C6: Caroline
A7: Mathematics Department (IP) | B7: E101 | C7: Marcus Goh
A8: Mathematics Department (JC) | B8: E102 | C8: Kheng Kiat
A9: Mother Tongue Department (IP) | B9: B109 | C9: Lay Pheng
A10: Mother Tongue Department (JC) | B10: B110 | C10: Chee Wai
A11: Physical Education Department | B11: E103 | C11: Irwan
A12: Learning, Extension and Application (LEAPS) | B12: E104 | C12: Jolene
... A14: Science Department (JC) | B14: E106 | C14: Miaohui

Sheet DATA NOTES
A1: Source Data Notes
A2: Issue | B2: Participant | C2: Impact | D2: Recommended action
A3: Missing Breakout 1 allocation in source | B3: Jismyl Lam | C3: Breakout 1 details are blank in the search result. | D3: Confirm the allocation and update columns D–F in PARTICIPANT DIRECTORY.
A4: Missing Breakout 1 allocation in source | B4: Sasha Kaur Dhillon | C4: Breakout 1 details are blank in the search result. | D4: Confirm the allocation and update columns D–F in PARTICIPANT DIRECTORY.
A5: Missing Breakout 2 allocation in source | B5: Mark Chan | C5: Breakout 2 details are blank in the search result. | D5: Confirm the allocation and update columns I–K in PARTICIPANT DIRECTORY.
A6: Department selected by each user | B6: All participants | C6: Reflection details appear after the user selects a department. | D6: Use the green department dropdown on the SEARCH sheet.
